Workbook
Name Number_of_years: '[1]Discount factors'!$B$6:$B$55

Sheet Authors
A1: Spreadsheet for the economic analysis of APSs: Ethiopia's Moderate Cement Plant category.
A2: Authors: | B2: Email | C2: Institutions
A3: Micheal G. Wolde | B3: mickfeke@gmail.com
B5: mwolde@kth.se
A6: Dr. Dilip Khatiwada. | B6: dilip.khatiwada@energy.kth.se

Sheet Data, Utilities, Consumabales
A2: Utilities, Consumables, Transport | B2: Unit Price | D2: Price Reference year | E2: Amount | F2: Reference case (plant without APS) | G2: Scenario A-APS | H2: Scenario B-APS | I2: Scenario C-APS | J2: Scenario D-APS | K2: Scenario E-APS | L2: Scenario F-APS | M2: Scenario F-APS
A3: Raw Meal | B3: $/t clinker | C3: 5.9 | D3: 2020 | E3: $/t clinker | F3: =5.9 -> 5.9 | G3: =F3 -> 5.9 | H3: =F3 -> 5.9 | I3: =F3 -> 5.9 | J3: =F3 -> 5.9 | K3: =F3 -> 5.9 | L3: =F3 -> 5.9 | M3: =F3 -> 5.9 | N3: OPEX part | P3: Reference case (plant without APS) | Q3: Scenario A-APS | R3: Scenario B-APS | S3: Scenario C-APS | T3: Scenario D-APS | U3: Scenario E-APS | V3: Scenario F-APS | W3: Scenario Ideal
A4: Cement additives | B4: $/t cement | C4: 3.1 | D4: 2020 | E4: $/t clinker | F4: =C4/E17 -> 4.4285714 | G4: =F4 -> 4.4285714 | H4: =F4 -> 4.4285714 | I4: =F4 -> 4.4285714 | J4: =F4 -> 4.4285714 | K4: =F4 -> 4.4285714 | L4: =F4 -> 4.4285714 | M4: =F4 -> 4.4285714 | N4: Total Cost | O4: $/t clinker | P4: =SUM(F3:F14) -> 70.374153 | Q4: =SUM(G3:G14) -> 65.995798 | R4: =SUM(H3:H14) -> 65.878328 | S4: =SUM(I3:I14) -> 65.9149 | T4: =SUM(J3:J14) -> 66.027163 | U4: =SUM(K3:K14) -> 45.671953 | V4: =SUM(L3:L14) -> 45.933248 | W4: =SUM(M3:M14) -> 29.009347
A5: Electricity | B5: $/KWh | C5: 0.03 | D5: 2020 | E5: $/t clinker | F5: =C5*E28 -> 4.0791 | G5: =C5*E29 -> 3.1122 | H5: =C5*E30 -> 3.0714 | I5: =C5*E31 -> 3.096 | J5: =C5*E32 -> 3.1122 | K5: =C5*E33 -> 3.1413 | L5: =C5*E34 -> 3.2388 | M5: =C5*E35 -> 3.0951 | O5: $/t cement | P5: =P4*$E$17 -> 49.261907 | Q5: =Q4*$E$17 -> 46.197058 | R5: =R4*$E$17 -> 46.114829 | S5: =S4*$E$17 -> 46.14043 | T5: =T4*$E$17 -> 46.219014 | U5: =U4*$E$17 -> 31.970367 | V5: =V4*$E$17 -> 32.153273 | W5: =W4*$E$17 -> 20.306543
A6: Coal | B6: $/GJ | C6: 10.1 | D6: 2020 | E6: $/t clinker | F6: =C6*E20 -> 35.855 | G6: =C6*E21 -> 32.724 | H6: =C6*E22 -> 32.724 | I6: =C6*E23 -> 32.724 | J6: =C6*E24 -> 32.724 | K6: =C6*E25 -> 14.746 | L6: =C6*E26 -> 14.746 | M6: =C6*E27 -> 0
A7: Diesel | B7: $/t clinker | C7: 1.4 | D7: 2020 | E7: $/t clinker | F7: =C7 -> 1.4 | G7: =F7 -> 1.4 | H7: =F7 -> 1.4 | I7: =F7 -> 1.4 | J7: =F7 -> 1.4 | K7: =F7 -> 1.4 | L7: =F7 -> 1.4 | M7: =C7 -> 1.4
A8: Water | B8: $/t clinker | C8: 0.07 | D8: 2013 | E8: $/t clinker | F8: =(C8*B48/100)+C8 -> 0.078624 | G8: =F8 -> 0.078624 | H8: =F8 -> 0.078624 | I8: =F8 -> 0.078624 | J8: =F8 -> 0.078624 | K8: =F8 -> 0.078624 | L8: =F8 -> 0.078624 | M8: =F8 -> 0.078624
A9: Explosives | B9: $/t clinker | C9: 0.42 | D9: 2020 | E9: $/t clinker | F9: =C9 -> 0.42 | G9: =F9 -> 0.42 | H9: =F9 -> 0.42 | I9: =F9 -> 0.42 | J9: =F9 -> 0.42 | K9: =F9 -> 0.42 | L9: =F9 -> 0.42 | M9: =F9 -> 0.42
A10: Other Materials | B10: $/t cement | C10: 9.27 | D10: 2020 | E10: $/t clinker | F10: =C10/E17 -> 13.242857 | G10: =F10 -> 13.242857 | H10: =F10 -> 13.242857 | I10: =F10 -> 13.242857 | J10: =F10 -> 13.242857 | K10: =F10 -> 13.242857 | L10: =F10 -> 13.242857 | M10: =F10 -> 13.242857
A11: Fossil Fuel Transport | B11: $/GJ | C11: 1.4 | D11: 2020 | E11: $/t clinker | F11: =C11*E20 -> 4.97 | G11: =C11*E21 -> 4.536 | H11: =C11*E22 -> 4.536 | I11: =C11*E23 -> 4.536 | J11: =C11*E24 -> 4.536 | K11: =C11*E25 -> 2.044 | L11: =C11*E26 -> 2.044 | M11: =C11*E27 -> 0
A12: PJDF Transport | B12: $/t AF | C12: 4.1 | D12: 2020 | E12: $/t clinker | F12: 0 | G12: 0 | H12: 0 | I12: =C12*(21.67/1000) -> 0.088847 | J12: =C12*(45.1/1000) -> 0.18491 | K12: =C12*(66/1000) -> 0.2706 | L12: =C12*(105.95/1000) -> 0.434395 | M12: =C12*(108.34/1000) -> 0.444194
A13: RDF Transport | B13: $/t AF | E13: $/t clinker | F13: 0 | G13: =C12*(37.45/1000) -> 0.153545 | H13: 0 | I13: 0 | J13: 0
A14: TDF Transport | B14: $/t AF | E14: $/t clinker | F14: 0 | G14: 0 | H14: =C12*(18.75/1000) -> 0.076875 | I14: 0 | J14: 0
A16: Parameter (data) | G16: Remark
A17: Clinker to Cement ratio | B17: 0.7 | E17: 0.7 | F17: -
A18: Capacity_factor (Cement plant) | E18: 0.9 | F18: %
A19: Operation hours (RDF/PJDF/TDF plants) | E19: 8000 | F19: hours
A20: Coal (reference Cement plant) | E20: 3.55 | F20: GJ/t clinker
A21: Coal (Scenario A-APS) | E21: 3.24 | F21: GJ/t clinker | G21: RDF required 37.45kg/t clinker
A22: Coal (Scenario B-APS) | E22: 3.24 | F22: GJ/t clinker | G22: RDF required 18.67kg/t clinker
A23: Coal (Scenario C-APS) | E23: 3.24 | F23: GJ/t clinker | G23: PJDF_Charcoal required 21.67kg/t clinker
A24: Coal (Scenario D-APS) | E24: 3.24 | F24: GJ/t clinker | G24: PJDF_Wood pellet required 45.1kg/t clinker
A25: Coal (Scenario E-APS) | E25: 1.46 | F25: GJ/t clinker | G25: Blended AF required 66kg/t clinker
A26: Coal (Scenario F-APS) | E26: 1.46 | F26: GJ/t clinker | G26: Blended AF required 105.95kg/t clinker
A27: Coal (Sceanrio Ideal-APS) | E27: 0 | F27: GJ/t clinker | G27: PJDF_Charcoal required 108.34kg/t clinker
A28: Electricity (reference Cement plant) | E28: 135.97 | F28: KWh/t clinker | G28: Values are determined based on the consumption change (reduction in %) from the reference case.
A29: Electricity ( Scenario A-APS) | E29: 103.74 | F29: KWh/t clinker
A30: Electricity (Scenario B-APS) | E30: 102.38 | F30: KWh/t clinker
A31: Electricity (Scenario C-APS) | E31: 103.2 | F31: KWh/t clinker
A32: Electricity (Scenario D-APS) | E32: 103.74 | F32: KWh/t clinker
A33: Electricity (Scenario E-APS) | E33: 104.71 | F33: KWh/t clinker
A34: Electricity (Scenario F-APS) | E34: 107.96 | F34: KWh/t clinker
A35: Electricity (Scenario Ideal) | E35: 103.17 | F35: KWh/t clinker
A37: Financial Data
A38: Discount rate | F38: 0.3 | G38: %
A39: Reference year | F39: 2020 | G39: -
A40: Operation years | F40: 20 | G40: y
A41: local tax and Insurance | F41: 2 | G41: % of capital cost
A42: labor Cost for cement plant site | F42: 2177.5 | G42: $/person/year
A43: Maintenance cost for the cement plant site | F43: 25 | G43: % of the total manufacturing cost
...

Sheet Economic & COeq emission Abat. 
B1: Calculate the cost of clinker/Cement
B2: Plant Data | E2: Reference case (plant without APS) | F2: Scenario A-APS | G2: Scenario B-APS | H2: Scenario C-APS | I2: Scenario D-APS | J2: Scenario E-APS | K2: Scenario F-APS | L2: Scenario Ideal | M2: Cost Breakdown | N2: Reference case (plant without APS) | P2: Scenario A-APS | R2: Scenario B-APS | T2: Scenario C-APS | V2: Scenario D-APS | X2: Scenario E-APS | Z2: Scenario F-APS | AB2: Scenario Ideal-APS
B3: Clinker Production | C3: Clinker production | D3: t clinker/day | E3: 3562 | F3: 3562 | G3: 3562 | H3: 3562 | I3: 3562 | J3: 3562 | K3: 3562 | L3: 3562 | M3: Product (cost) | N3: Clinker ($/t clinker) | O3: Cement ($/t cement | P3: Clinker ($/t clinker) | Q3: Cement ($/t cement | R3: Clinker ($/t clinker) | S3: Cement ($/t cement | T3: Clinker ($/t clinker) | U3: Cement ($/t cement | V3: Clinker ($/t clinker) | W3: Cement ($/t cement | X3: Clinker ($/t clinker) | Y3: Cement ($/t cement | Z3: Clinker ($/t clinker) | AA3: Cement ($/t cement | AB3: Clinker ($/t clinker) | AC3: Cement ($/t cement
C4: Cement to clinker ratio | D4: t cement/t clinker | E4: 1.42 | F4: 1.42 | G4: 1.42 | H4: 1.42 | I4: 1.42 | J4: 1.42 | K4: 1.42 | L4: 1.42
C5: Cement production | D5: t cement/day | E5: 5089 | F5: 5089 | G5: 5089 | H5: 5089 | I5: 5089 | J5: 5089 | K5: 5089 | L5: 5089 | M5: Annualized CAPEX | N5: =(E$28*1000000/(0.9*365*$E$3)) -> 44.963426 | O5: =(E$28*1000000/(0.9*365*E5)) -> 31.471747 | P5: =(F28*1000000/(0.9*365*$E$3)) -> 53.60019 | Q5: =(F28*1000000/(0.9*365*E5)) -> 37.516973 | R5: =(G28*1000000/(0.9*365*$E$3)) -> 52.360987 | S5: =(G28*1000000/(0.9*365*E5)) -> 36.649604 | T5: =(H28*1000000/(0.9*365*$E$3)) -> 53.38366 | U5: =(H28*1000000/(0.9*365*E5)) -> 37.365415 | V5: =(I28*1000000/(0.9*365*$E$3)) -> 53.38366 | W5: =(I28*1000000/(0.9*365*F5)) -> 37.365415 | X5: =(J28*1000000/(0.9*365*$E$3)) -> 56.357629 | Y5: =(J28*1000000/(0.9*365*F5)) -> 39.447018 | Z5: =(K28*1000000/(0.9*365*$E$3)) -> 56.357629 | AA5: =(K28*1000000/(0.9*365*E5)) -> 39.447018 | AB5: =(L28*1000000/(0.9*365*$E$3)) -> 52.16594 | AC5: =(L28*1000000/(0.9*365*E5)) -> 36.513083
B6: CO2-eq emissions | C6: Includes direct emissions (kiln_Calcination and Fuel Burning) and Indirect emissions (Electricity, transport, fossil fuel production). Note: weighted average values considered, calculated based on the production volume of cement products (PPC and OPC) | D6: Kg CO2-eq/t cement | E6: 636.84 | F6: 589.49 | G6: 596.96 | H6: 569.39 | I6: 569.4 | J6: 509.53 | K6: 510.63 | L6: 381.41 | M6: Total OPEX | N6: =(E51*1000000/(0.9*365*$E$3)) -> 83.727839 | O6: =(E51*1000000/(0.9*365*E5)) -> 58.604551 | P6: =(F51*1000000/(0.9*365*$E$3)) -> 93.499461 | Q6: =(F51*1000000/(0.9*365*E5)) -> 65.444111 | R6: =(G51*1000000/(0.9*365*$E$3)) -> 84.435462 | S6: =G51*1000000/(0.9*365*E5) -> 59.099846 | T6: =(H51*1000000/(0.9*365*$E$3)) -> 87.212009 | U6: =(H51*1000000/(0.9*365*E5)) -> 61.043265 | V6: =(I51*1000000/(0.9*365*$E$3)) -> 87.324272 | W6: =(I51*1000000/(0.9*365*F5)) -> 61.121843 | X6: =(J51*1000000/(0.9*365*$E$3)) -> 78.78908 | Y6: =(J51*1000000/(0.9*365*F5)) -> 55.147711 | Z6: =(K51*1000000/(0.9*365*$E$3)) -> 79.050375 | AA6: =(K51*1000000/(0.9*365*E5)) -> 55.330602 | AB6: =(L51*1000000/(0.9*365*$E$3)) -> 51.247336 | AC6: =(L51*1000000/(0.9*365*E5)) -> 35.870114
M7: Total Cost of Clinker/Cement | N7: =SUM(N5:N6) -> 128.69126 | O7: =SUM(O5:O6) -> 90.076299 | P7: =SUM(P5:P6) -> 147.09965 | Q7: =SUM(Q5:Q6) -> 102.96108 | R7: =SUM(R5:R6) -> 136.79645 | S7: =SUM(S5:S6) -> 95.74945 | T7: =SUM(T5:T6) -> 140.59567 | U7: =SUM(U5:U6) -> 98.40868 | ... AC7: =SUM(AC5:AC6) -> 72.383197
O8: =O7*E53 -> 1.5058384e+08
B9: CAPEX and OPEX | M9: CO2-eq emissions abated/avoided | N9: Reference case (plant without APS) | O9: Scenario A-APS | P9: Scenario B-APS | Q9: Scenario C-APS | R9: Scenario D-APS | S9: Scenario E-APS | T9: Scenario F-APS | U9: Scenario Ideal-APS
B10: CAPEX | C10: Cement plant only (existing) | D10: Million USD2020 | E10: 245 | F10: 245 | G10: 245 | H10: 245 | I10: 245 | J10: 245 | K10: 245 | L10: 245 | M10: Marginal Abatement Cost of CO2eq- Emissions ($/t CO2-eq) | N10: N/A | O10: =(Q7-$O$7)/(($E$6/1000)-(F6/1000)) -> 272.11795 | P10: =(S7-$O$7)/(($E$6/1000)-(G6/1000)) -> 142.25555 | Q10: =(U7-$O$7)/(($E$6/1000)-(H6/1000)) -> 123.5342 | R10: =(W7-$O$7)/(($E$6/1000)-(I6/1000)) -> 124.71767 | S10: =(Y7-$O$7)/(($E$6/1000)-(J6/1000)) -> 35.491562 | T10: =(AA7-$O$7)/(($E$6/1000)-(K6/1000)) -> 37.249994 | U10: =(AC7-$O$7)/(($E$6/1000)-(L6/1000)) -> -69.267905
C11: RDF plant only | D11: Million USD2020 | F11: =((10*(POWER(D58,E58)))*F58)*(1+0%) -> 7.329119 | M11: Total Amount of CO2-eq Emsissions abated/avoided (mt CO2-eq, 2020) | N11: N/A | O11: =(($E$6-$F6)/1000)*(0.9*365*$F$5) -> 79156.723 | P11: =(($E$6-G6)/1000)*(0.9*365*$F$5) -> 66668.852 | Q11: =(($E$6-H6)/1000)*(0.9*365*$F$5) -> 112758.63 | R11: =(($E$6-I6)/1000)*(0.9*365*$F$5) -> 112741.91 | S11: =(($E$6-J6)/1000)*(0.9*365*$F$5) -> 212828.77 | T11: =(($E$6-K6)/1000)*(0.9*365*$F$5) -> 210989.86 | U11: =(($E$6-L6)/1000)*(0.9*365*$F$5) -> 427011.65
C12: TDF plant only | D12: Million USD2020 | G12: =(1.13*(POWER(D59,E59))*F59)*(1+0%) -> 1.1865 | M12: Total Amount of CO2-eq Emsissions abated/avoided (mt CO2-eq, from 2020 to 2030) | N12: N/A | O12: =10*O$11 -> 791567.23 | P12: =10*P$11 -> 666688.52 | Q12: =10*Q$11 -> 1127586.3 | R12: =10*R$11 -> 1127419.1 | S12: =10*S$11 -> 2128287.7 | T12: =10*T$11 -> 2109898.6 | U12: =U11*10 -> 4270116.5
C13: PJDF (Cost includes PJDF production site and cement plant site equipment/process) | D13: Million USD2020 | H13: =(7.55*(POWER(D60,E60))*F60)*(1+0%) -> 9.3603338 | I13: =(7.55*(POWER(D60,E60))*F60)*(1+0%) -> 9.3603338 | J13: =SUM(F11,G12,H13) -> 17.875953 | K13: =SUM(F11,G12,I13) -> 17.875953 | L13: =(7.55*(POWER(D60,E60))*F60)*(1+0%) -> 9.3603338 | M13: Contribution in % (reduction) to Ethiopia's climate plan (target reduction - 9.2 million t of CO2-eq by 2030 | N13: N/A | O13: =O$12/9200000 -> 0.086039917 | P13: =P$12/9200000 -> 0.072466143 | Q13: =Q$12/9200000 -> 0.12256372 | R13: =R$12/9200000 -> 0.12254555 | S13: =S$12/9200000 -> 0.23133562 | T13: =T$12/9200000 -> 0.22933681 | U13: =U$12/9200000 -> 0.4641431
C14: Typical cement plant upgrades/retrofits required for AFs use (in particular RDF and TDF) | D14: Million USD2020 | F14: =(2.96*F61) -> 3.108 | G14: =2.96*F61 -> 3.108 | J14: =G14*2 -> 6.216 | K14: =G14*2 -> 6.216 | L14: =H14*2 -> 0 | M14: Total Amount of CO2-eq Emsissions (t CO2-eq, from 2020 to 2030) for APS | O14: =((F6/1000)*(0.9*365*F5))*10 -> 9854719.5 | P14: =((G6/1000)*(0.9*365*G5))*10 -> 9979598.2 | Q14: =((H6/1000)*(0.9*365*H5))*10 -> 9518700.5 | R14: =((I6/1000)*(0.9*365*I5))*10 -> 9518867.6 | S14: =((J6/1000)*(0.9*365*J5))*10 -> 8517999 | T14: =((K6/1000)*(0.9*365*K5))*10 -> 8536388.1 | U14: =((L6/1000)*(0.9*365*L5))*10 -> 6376170.2
C15: Kiln combustion system improvements in rotary kilns (Oxygen enrichment Technology) | D15: Million USD2020 | F15: =(6.5*$F$62) -> 6.825 | G15: =6.5*$F$62 -> 6.825 | H15: =6.5*$F$62 -> 6.825 | I15: =6.5*$F$62 -> 6.825 | J15: =6.5*$F$62 -> 6.825 | K15: =6.5*$F$62 -> 6.825 | L15: =6.5*$F$62 -> 6.825 | M15: Reference case (plant without APS) | O15: =(N17-O14)/N17 -> 0.074351485 | P15: =(N17-P14)/N17 -> 0.062621695 | Q15: =(N17-Q14)/N17 -> 0.10591357 | R15: =(N17-R14)/N17 -> 0.10589787 | S15: =(N17-S14)/N17 -> 0.19990893 | T15: =(N17-T14)/N17 -> 0.19818165 | U15: =(N17-U14)/N17 -> 0.40108976
C16: Kiln combustion system improvements in rotary kilns (Multi-channel kiln burner) | D16: Million USD2020 | F16: =(0.3*$F$62) -> 0.315 | G16: =0.3*$F$62 -> 0.315 | H16: =0.3*$F$62 -> 0.315 | I16: =0.3*$F$62 -> 0.315 | J16: =0.3*$F$62 -> 0.315 | K16: =0.3*$F$62 -> 0.315 | L16: =0.3*$F$62 -> 0.315 | M16: Total Amount of CO2-eq Emsissions (t CO2-eq, 2020) | N16: =(E6/1000)*(0.9*365*F5) -> 1064628.7 | O16: =($N$16-($N$16-O11))/$N$16 -> 0.074351485 | P16: =($N$16-($N$16-P11))/$N$16 -> 0.062621695 | Q16: =($N$16-($N$16-Q11))/$N$16 -> 0.10591357 | R16: =($N$16-($N$16-R11))/$N$16 -> 0.10589787 | S16: =($N$16-($N$16-S11))/$N$16 -> 0.19990893 | T16: =($N$16-($N$16-T11))/$N$16 -> 0.19818165 | U16: =($N$16-($N$16-U11))/$N$16 -> 0.40108976 | V16: Change/decrease
C17: Energy management and process control systems for clinker-making | D17: Million USD2020 | F17: =(1.3*$F$63) -> 1.352 | G17: =1.3*$F$63 -> 1.352 | H17: =1.3*$F$63 -> 1.352 | I17: =1.3*$F$63 -> 1.352 | J17: =1.3*$F$63 -> 1.352 | K17: =1.3*$F$63 -> 1.352 | L17: =1.3*$F$63 -> 1.352 | M17: Total Amount of CO2-eq Emsissions (t CO2-eq, from 2020 to 2030) | N17: =10*N16 -> 10646287 | O17: =($N$17-($N$17-$O$12))/$N$17 -> 0.074351485 | P17: =($N$17-($N$17-P12))/$N$17 -> 0.062621695 | Q17: =($N$17-($N$17-Q12))/$N$17 -> 0.10591357 | R17: =($N$17-($N$17-R12))/$N$17 -> 0.10589787 | S17: =($N$17-($N$17-S12))/$N$17 -> 0.19990893 | T17: =($N$17-($N$17-T12))/$N$17 -> 0.19818165 | U17: =($N$17-($N$17-U12))/$N$17 -> 0.40108976
C18: High-efficiency fans for cement mill | D18: Million USD2020 | F18: =(0.03*$F$64)*(1-10%) -> 0.02835 | G18: =0.03*$F$64 -> 0.0315 | H18: =0.03*$F$64 -> 0.0315 | I18: =0.03*$F$64 -> 0.0315 | J18: =0.03*$F$64 -> 0.0315 | K18: =0.03*$F$64 -> 0.0315 | L18: =0.03*$F$64 -> 0.0315
C19: Roller mills for fuel preparation | D19: Million USD2020 | F19: =(0.06*$F$65) -> 0.0648 | G19: =0.06*$F$65 -> 0.0648 | H19: =0.06*$F$65 -> 0.0648 | I19: =0.06*$F$65 -> 0.0648 | J19: =0.06*$F$65 -> 0.0648 | K19: =0.06*$F$65 -> 0.0648 | L19: =0.06*$F$65 -> 0.0648
C20: High Efficiency motors and drives | D20: Million USD2020 | F20: =(0.25*$F$66) -> 0.26 | G20: =0.25*$F$66 -> 0.26 | H20: =0.25*$F$66 -> 0.26 | I20: =0.25*$F$66 -> 0.26 | J20: =0.25*$F$66 -> 0.26 | K20: =0.25*$F$66 -> 0.26 | L20: =0.25*$F$66 -> 0.26
C21: Adjustable or variable speed drives | D21: Million USD2020 | F21: =(1.65*$F$67) -> 1.716 | G21: =1.65*$F$67 -> 1.716 | H21: =1.65*$F$67 -> 1.716 | I21: =1.65*$F$67 -> 1.716 | J21: =1.65*$F$67 -> 1.716 | K21: =1.65*$F$67 -> 1.716 | L21: =1.65*$F$67 -> 1.716
C22: Optimizing the operation of cement mill | D22: Million USD2020 | F22: =(0.01*$F$68)*(1-10%) -> 0.00945 | G22: =0.01*$F$68 -> 0.0105 | H22: =0.01*$F$68 -> 0.0105 | I22: =0.01*$F$68 -> 0.0105 | J22: =0.01*$F$68 -> 0.0105 | K22: =0.01*$F$68 -> 0.0105 | L22: =0.01*$F$68 -> 0.0105
C23: Improved grinding media (for ball mills) | D23: Million USD2020 | F23: =(1.84*$F$69) -> 1.9136 | G23: =1.84*$F$69 -> 1.9136 | H23: =1.84*$F$69 -> 1.9136 | I23: =1.84*$F$69 -> 1.9136 | J23: =1.84*$F$69 -> 1.9136 | K23: =1.84*$F$69 -> 1.9136 | L23: =1.84*$F$69 -> 1.9136
C24: Waste Heat Recovery Power Plant (WHRP) | D24: Million USD2020 | F24: =(5.8*F70) -> 6.032 | G24: =5.8*F70 -> 6.032 | H24: =5.8*F70 -> 6.032 | I24: =5.8*F70 -> 6.032 | J24: =5.8*F70 -> 6.032 | K24: =5.8*F70 -> 6.032 | L24: =5.8*G70 -> 0
C25: SNCR (Selective Non-Catalytic Reduction) for NOx emissions abatement | D25: Million USD2020 | F25: =(1.5*(POWER($D$71,$E$71))*$F$71) -> 2.0080811 | G25: =1.5*(POWER($D$71,$E$71))*$F$71 -> 2.0080811 | H25: =1.5*(POWER($D$71,$E$71))*$F$71 -> 2.0080811 | I25: =1.5*(POWER($D$71,$E$71))*$F$71 -> 2.0080811 | J25: =1.5*(POWER($D$71,$E$71))*$F$71 -> 2.0080811 | K25: =1.5*(POWER($D$71,$E$71))*$F$71 -> 2.0080811 | L25: =1.5*(POWER($D$71,$E$71))*$F$71 -> 2.0080811
C26: Wet Scrubber for SOx emissions abatement | D26: Million USD2020 | F26: =(6.44*(POWER($D$72,$E$72))*$F$72) -> 11.820993 | G26: =6.44*(POWER($D$72,$E$72))*$F$72 -> 11.820993 | H26: =6.44*(POWER($D$72,$E$72))*$F$72 -> 11.820993 | I26: =6.44*(POWER($D$72,$E$72))*$F$72 -> 11.820993 | J26: =6.44*(POWER($D$72,$E$72))*$F$72 -> 11.820993 | K26: =6.44*(POWER($D$72,$E$72))*$F$72 -> 11.820993 | L26: =6.44*(POWER($D$72,$E$72))*$F$72 -> 11.820993
C27: Total CAPEX | D27: Million USD2021 | E27: =SUM(E10:E26) -> 245 | F27: =((SUM(F11:F26)+(D74)*SUM(F11:F26)))+F10 -> 292.06063 | G27: =((SUM(G11:G26)+($D$74)*SUM(G11:G26)))+G10 -> 285.30837 | H27: =((SUM(H11:H26)+($D$74)*SUM(H11:H26)))+H10 -> 290.88079 | I27: =((SUM(I11:I26)+($D$74)*SUM(I11:I26)))+I10 -> 290.88079 | J27: =((SUM(J11:J26)+($D$74)*SUM(J11:J26)))+J10 -> 307.08557 | K27: =((SUM(K11:K26)+($D$74)*SUM(K11:K26)))+K10 -> 307.08557 | L27: =((SUM(L11:L26)+($D$74)*SUM(L11:L26)))+L10 -> 284.24559
C28: Annualized CAPEX | D28: Million USD2020/year | E28: =PMT($D$75,$D$76,-E$27) -> 52.612469 | F28: =(PMT($D$75,$D$76,-F$27)) -> 62.718493 | G28: =PMT($D$75,$D$76,-G$27) -> 61.268481 | H28: =PMT($D$75,$D$76,-H$27) -> 62.465128 | I28: =PMT($D$75,$D$76,-I$27) -> 62.465128 | J28: =PMT($D$75,$D$76,-J$27) -> 65.94502 | K28: =PMT($D$75,$D$76,-K$27) -> 65.94502 | L28: =PMT($D$75,$D$76,-L$27) -> 61.040254
B29: OPEX | C29: RDF plant only | D29: Million USD2020/Year | F29: =10.6*(1+G58) -> 11.90592 | J29: =F29 -> 11.90592 | K29: =J29 -> 11.90592
C30: TDF plant only | D30: Million USD2020/year | G30: =1.4*(1+G58) -> 1.57248 | J30: =G30 -> 1.57248 | K30: =J30 -> 1.57248
C31: PJDF (Cost includes PJDF production site and cement plant site equipment/process) | D31: Million USD2020/year | H31: =4.13*(1+G58) -> 4.638816 | I31: 4.638816 | J31: =H31 -> 4.638816 | K31: =J31 -> 4.638816 | L31: =4.13*(1+K58) -> 4.13
C32: Kiln combustion system improvements in rotary kilns (Oxygen enrichment Technology)_Change in OPEX | D32: Million USD2020/Year | F32: =2.18*(1+G58) -> 2.448576 | G32: 2.448576 | H32: 2.448576 | I32: 2.448576 | J32: 2.448576 | K32: 2.448576 | L32: 2.448576
C33: Kiln combustion system improvements in rotary kilns (Oxygen enrichment Technology)_Change in OPEX | D33: Million USD2020/year | F33: =-0.23*(1+G58) -> -0.258336 | G33: -0.258336 | H33: -0.258336 | I33: -0.258336 | J33: -0.258336 | K33: -0.258336 | L33: -0.258336
C34: Energy management and process control systems for clinker-making_Change in OPEX | D34: Million USD2020/year | F34: 0 | G34: 0 | H34: 0 | I34: 0 | J34: 0 | K34: 0 | L34: 0
C35: High-efficiency fans for cement mill_Change in OPEX | D35: Million USD2020/Year | F35: 0.025 | G35: 0.025 | H35: 0.025 | I35: 0.025 | J35: 0.025 | K35: 0.025 | L35: 0.025
C36: Roller mills for fuel preparation_Change in OPEX | D36: Million USD2020/year | F36: 0 | G36: 0 | H36: 0 | I36: 0 | J36: 0 | K36: 0 | L36: 0
C37: High Efficiency motors and drives_Change in OPEX | D37: Million USD2020/year | F37: 0 | G37: 0 | H37: 0 | I37: 0 | J37: 0 | K37: 0 | L37: 0
C38: Adjustable or variable speed drives_Change in OPEX | D38: Million USD2020/Year | F38: 0 | G38: 0 | H38: 0 | I38: 0 | J38: 0 | K38: 0 | L38: 0
C39: Optimizing the operation of cement mill_Change in OPEX | D39: Million USD2020/year | F39: =-0.4*(1+G58) -> -0.44928 | G39: -0.44928 | H39: -0.44928 | I39: -0.44928 | J39: -0.44928 | K39: -0.44928 | L39: -0.44928
C40: Improved grinding media (for ball mills)_Change in OPEX | D40: Million USD2020/year | F40: 0 | G40: 0 | H40: 0 | I40: 0 | J40: 0 | K40: 0 | L40: 0
...

Sheet MACC 
A1: MACC
A2: Scenarios | B2: $/t CO2-eq | C2: Total Amount of CO2-eq Emsissions abated/avoided (million t CO2-eq, 2020)
A3: Scenario Ideal-APS | B3: ='Economic & COeq emission Abat. '!U10 -> -69.267905 | C3: =('Economic & COeq emission Abat. '!U11)/1000000 -> 0.42701165
A4: Scenario E-APS | B4: ='Economic & COeq emission Abat. '!S10 -> 35.491562 | C4: =('Economic & COeq emission Abat. '!S11)/1000000 -> 0.21282877
A5: Scenario F-APS | B5: ='Economic & COeq emission Abat. '!T10 -> 37.249994 | C5: =('Economic & COeq emission Abat. '!T11)/1000000 -> 0.21098986
A6: Scenario C-APS | B6: ='Economic & COeq emission Abat. '!Q10 -> 123.5342 | C6: =('Economic & COeq emission Abat. '!Q11)/1000000 -> 0.11275863
A7: Scenario D-APS | B7: ='Economic & COeq emission Abat. '!R10 -> 124.71767 | C7: =('Economic & COeq emission Abat. '!R11)/1000000 -> 0.11274191
A8: Scenario B-APS | B8: ='Economic & COeq emission Abat. '!P10 -> 142.25555 | C8: =('Economic & COeq emission Abat. '!P11)/1000000 -> 0.066668852
A9: Scenario A-APS | B9: ='Economic & COeq emission Abat. '!O10 -> 272.11795 | C9: =('Economic & COeq emission Abat. '!O11)/1000000 -> 0.079156723
